INFO:     Started server process [95974]
INFO:     Waiting for application startup.
INFO:     Application startup complete.
INFO:     Uvicorn running on http://0.0.0.0:8000 (Press CTRL+C to quit)
Loading and parsing files from _context directory...
Warning: _context directory not found. Using sample data.
INFO:     127.0.0.1:65509 - "GET /parse-status HTTP/1.1" 200 OK
INFO:     Shutting down
INFO:     Waiting for application shutdown.
INFO:     Application shutdown complete.
INFO:     Finished server process [95974]
INFO:     Started server process [96047]
INFO:     Waiting for application startup.
INFO:     Application startup complete.
INFO:     Uvicorn running on http://0.0.0.0:8000 (Press CTRL+C to quit)
Loading and parsing files from _context directory...
Successfully parsed 10 files
Found 178 courses
Found 9 requirements

Sample courses found:
  - BX 101: I
  - BX 201E: R
  - HB 101: o
INFO:     127.0.0.1:49158 - "GET /parse-status HTTP/1.1" 200 OK
INFO:     Shutting down
INFO:     Waiting for application shutdown.
INFO:     Application shutdown complete.
INFO:     Finished server process [96047]
INFO:     Started server process [96087]
INFO:     Waiting for application startup.
INFO:     Application startup complete.
INFO:     Uvicorn running on http://0.0.0.0:8000 (Press CTRL+C to quit)
Loading and parsing files from _context directory...
Successfully parsed 10 files
Found 170 courses
Found 9 requirements

Sample courses found:
  - BX101: Introduction to the Bible
  - BX201E: Reading Practicum: The One God and the Other
  - HB101: or NT 101
INFO:     127.0.0.1:49182 - "GET /parse-status HTTP/1.1" 200 OK
INFO:     127.0.0.1:49434 - "GET /courses HTTP/1.1" 200 OK
INFO:     127.0.0.1:49435 - "GET /requirements HTTP/1.1" 500 Internal Server Error
ERROR:    Exception in ASGI application
Traceback (most recent call last):
  File "/Users/jazmin/Library/Python/3.9/lib/python/site-packages/uvicorn/protocols/http/httptools_impl.py", line 426, in run_asgi
    result = await app(  # type: ignore[func-returns-value]
  File "/Users/jazmin/Library/Python/3.9/lib/python/site-packages/uvicorn/middleware/proxy_headers.py", line 84, in __call__
    return await self.app(scope, receive, send)
  File "/Users/jazmin/Library/Python/3.9/lib/python/site-packages/fastapi/applications.py", line 1106, in __call__
    await super().__call__(scope, receive, send)
  File "/Users/jazmin/Library/Python/3.9/lib/python/site-packages/starlette/applications.py", line 122, in __call__
    await self.middleware_stack(scope, receive, send)
  File "/Users/jazmin/Library/Python/3.9/lib/python/site-packages/starlette/middleware/errors.py", line 184, in __call__
    raise exc
  File "/Users/jazmin/Library/Python/3.9/lib/python/site-packages/starlette/middleware/errors.py", line 162, in __call__
    await self.app(scope, receive, _send)
  File "/Users/jazmin/Library/Python/3.9/lib/python/site-packages/starlette/middleware/cors.py", line 91, in __call__
    await self.simple_response(scope, receive, send, request_headers=headers)
  File "/Users/jazmin/Library/Python/3.9/lib/python/site-packages/starlette/middleware/cors.py", line 146, in simple_response
    await self.app(scope, receive, send)
  File "/Users/jazmin/Library/Python/3.9/lib/python/site-packages/starlette/middleware/exceptions.py", line 79, in __call__
    raise exc
  File "/Users/jazmin/Library/Python/3.9/lib/python/site-packages/starlette/middleware/exceptions.py", line 68, in __call__
    await self.app(scope, receive, sender)
  File "/Users/jazmin/Library/Python/3.9/lib/python/site-packages/fastapi/middleware/asyncexitstack.py", line 20, in __call__
    raise e
  File "/Users/jazmin/Library/Python/3.9/lib/python/site-packages/fastapi/middleware/asyncexitstack.py", line 17, in __call__
    await self.app(scope, receive, send)
  File "/Users/jazmin/Library/Python/3.9/lib/python/site-packages/starlette/routing.py", line 718, in __call__
    await route.handle(scope, receive, send)
  File "/Users/jazmin/Library/Python/3.9/lib/python/site-packages/starlette/routing.py", line 276, in handle
    await self.app(scope, receive, send)
  File "/Users/jazmin/Library/Python/3.9/lib/python/site-packages/starlette/routing.py", line 66, in app
    response = await func(request)
  File "/Users/jazmin/Library/Python/3.9/lib/python/site-packages/fastapi/routing.py", line 274, in app
    raw_response = await run_endpoint_function(
  File "/Users/jazmin/Library/Python/3.9/lib/python/site-packages/fastapi/routing.py", line 191, in run_endpoint_function
    return await dependant.call(**values)
  File "/Users/jazmin/_dev/degree_planner/cursor/backend/main.py", line 177, in get_requirements
    return [Requirement(**req) for req in requirements_data]
  File "/Users/jazmin/_dev/degree_planner/cursor/backend/main.py", line 177, in <listcomp>
    return [Requirement(**req) for req in requirements_data]
  File "/Users/jazmin/Library/Python/3.9/lib/python/site-packages/pydantic/main.py", line 164, in __init__
    __pydantic_self__.__pydantic_validator__.validate_python(data, self_instance=__pydantic_self__)
pydantic_core._pydantic_core.ValidationError: 1 validation error for Requirement
credits_required
  Input should be a valid integer [type=int_type, input_value=None, input_type=NoneType]
    For further information visit https://errors.pydantic.dev/2.5/v/int_type
INFO:     127.0.0.1:49434 - "GET /courses HTTP/1.1" 200 OK
INFO:     127.0.0.1:49437 - "GET /requirements HTTP/1.1" 500 Internal Server Error
ERROR:    Exception in ASGI application
Traceback (most recent call last):
  File "/Users/jazmin/Library/Python/3.9/lib/python/site-packages/uvicorn/protocols/http/httptools_impl.py", line 426, in run_asgi
    result = await app(  # type: ignore[func-returns-value]
  File "/Users/jazmin/Library/Python/3.9/lib/python/site-packages/uvicorn/middleware/proxy_headers.py", line 84, in __call__
    return await self.app(scope, receive, send)
  File "/Users/jazmin/Library/Python/3.9/lib/python/site-packages/fastapi/applications.py", line 1106, in __call__
    await super().__call__(scope, receive, send)
  File "/Users/jazmin/Library/Python/3.9/lib/python/site-packages/starlette/applications.py", line 122, in __call__
    await self.middleware_stack(scope, receive, send)
  File "/Users/jazmin/Library/Python/3.9/lib/python/site-packages/starlette/middleware/errors.py", line 184, in __call__
    raise exc
  File "/Users/jazmin/Library/Python/3.9/lib/python/site-packages/starlette/middleware/errors.py", line 162, in __call__
    await self.app(scope, receive, _send)
  File "/Users/jazmin/Library/Python/3.9/lib/python/site-packages/starlette/middleware/cors.py", line 91, in __call__
    await self.simple_response(scope, receive, send, request_headers=headers)
  File "/Users/jazmin/Library/Python/3.9/lib/python/site-packages/starlette/middleware/cors.py", line 146, in simple_response
    await self.app(scope, receive, send)
  File "/Users/jazmin/Library/Python/3.9/lib/python/site-packages/starlette/middleware/exceptions.py", line 79, in __call__
    raise exc
  File "/Users/jazmin/Library/Python/3.9/lib/python/site-packages/starlette/middleware/exceptions.py", line 68, in __call__
    await self.app(scope, receive, sender)
  File "/Users/jazmin/Library/Python/3.9/lib/python/site-packages/fastapi/middleware/asyncexitstack.py", line 20, in __call__
    raise e
  File "/Users/jazmin/Library/Python/3.9/lib/python/site-packages/fastapi/middleware/asyncexitstack.py", line 17, in __call__
    await self.app(scope, receive, send)
  File "/Users/jazmin/Library/Python/3.9/lib/python/site-packages/starlette/routing.py", line 718, in __call__
    await route.handle(scope, receive, send)
  File "/Users/jazmin/Library/Python/3.9/lib/python/site-packages/starlette/routing.py", line 276, in handle
    await self.app(scope, receive, send)
  File "/Users/jazmin/Library/Python/3.9/lib/python/site-packages/starlette/routing.py", line 66, in app
    response = await func(request)
  File "/Users/jazmin/Library/Python/3.9/lib/python/site-packages/fastapi/routing.py", line 274, in app
    raw_response = await run_endpoint_function(
  File "/Users/jazmin/Library/Python/3.9/lib/python/site-packages/fastapi/routing.py", line 191, in run_endpoint_function
    return await dependant.call(**values)
  File "/Users/jazmin/_dev/degree_planner/cursor/backend/main.py", line 177, in get_requirements
    return [Requirement(**req) for req in requirements_data]
  File "/Users/jazmin/_dev/degree_planner/cursor/backend/main.py", line 177, in <listcomp>
    return [Requirement(**req) for req in requirements_data]
  File "/Users/jazmin/Library/Python/3.9/lib/python/site-packages/pydantic/main.py", line 164, in __init__
    __pydantic_self__.__pydantic_validator__.validate_python(data, self_instance=__pydantic_self__)
pydantic_core._pydantic_core.ValidationError: 1 validation error for Requirement
credits_required
  Input should be a valid integer [type=int_type, input_value=None, input_type=NoneType]
    For further information visit https://errors.pydantic.dev/2.5/v/int_type
INFO:     None:0 - "GET /manifest.json HTTP/1.1" 404 Not Found
INFO:     127.0.0.1:49670 - "GET /courses HTTP/1.1" 200 OK
INFO:     127.0.0.1:49671 - "GET /requirements HTTP/1.1" 500 Internal Server Error
ERROR:    Exception in ASGI application
Traceback (most recent call last):
  File "/Users/jazmin/Library/Python/3.9/lib/python/site-packages/uvicorn/protocols/http/httptools_impl.py", line 426, in run_asgi
    result = await app(  # type: ignore[func-returns-value]
  File "/Users/jazmin/Library/Python/3.9/lib/python/site-packages/uvicorn/middleware/proxy_headers.py", line 84, in __call__
    return await self.app(scope, receive, send)
  File "/Users/jazmin/Library/Python/3.9/lib/python/site-packages/fastapi/applications.py", line 1106, in __call__
    await super().__call__(scope, receive, send)
  File "/Users/jazmin/Library/Python/3.9/lib/python/site-packages/starlette/applications.py", line 122, in __call__
    await self.middleware_stack(scope, receive, send)
  File "/Users/jazmin/Library/Python/3.9/lib/python/site-packages/starlette/middleware/errors.py", line 184, in __call__
    raise exc
  File "/Users/jazmin/Library/Python/3.9/lib/python/site-packages/starlette/middleware/errors.py", line 162, in __call__
    await self.app(scope, receive, _send)
  File "/Users/jazmin/Library/Python/3.9/lib/python/site-packages/starlette/middleware/cors.py", line 91, in __call__
    await self.simple_response(scope, receive, send, request_headers=headers)
  File "/Users/jazmin/Library/Python/3.9/lib/python/site-packages/starlette/middleware/cors.py", line 146, in simple_response
    await self.app(scope, receive, send)
  File "/Users/jazmin/Library/Python/3.9/lib/python/site-packages/starlette/middleware/exceptions.py", line 79, in __call__
    raise exc
  File "/Users/jazmin/Library/Python/3.9/lib/python/site-packages/starlette/middleware/exceptions.py", line 68, in __call__
    await self.app(scope, receive, sender)
  File "/Users/jazmin/Library/Python/3.9/lib/python/site-packages/fastapi/middleware/asyncexitstack.py", line 20, in __call__
    raise e
  File "/Users/jazmin/Library/Python/3.9/lib/python/site-packages/fastapi/middleware/asyncexitstack.py", line 17, in __call__
    await self.app(scope, receive, send)
  File "/Users/jazmin/Library/Python/3.9/lib/python/site-packages/starlette/routing.py", line 718, in __call__
    await route.handle(scope, receive, send)
  File "/Users/jazmin/Library/Python/3.9/lib/python/site-packages/starlette/routing.py", line 276, in handle
    await self.app(scope, receive, send)
  File "/Users/jazmin/Library/Python/3.9/lib/python/site-packages/starlette/routing.py", line 66, in app
    response = await func(request)
  File "/Users/jazmin/Library/Python/3.9/lib/python/site-packages/fastapi/routing.py", line 274, in app
    raw_response = await run_endpoint_function(
  File "/Users/jazmin/Library/Python/3.9/lib/python/site-packages/fastapi/routing.py", line 191, in run_endpoint_function
    return await dependant.call(**values)
  File "/Users/jazmin/_dev/degree_planner/cursor/backend/main.py", line 177, in get_requirements
    return [Requirement(**req) for req in requirements_data]
  File "/Users/jazmin/_dev/degree_planner/cursor/backend/main.py", line 177, in <listcomp>
    return [Requirement(**req) for req in requirements_data]
  File "/Users/jazmin/Library/Python/3.9/lib/python/site-packages/pydantic/main.py", line 164, in __init__
    __pydantic_self__.__pydantic_validator__.validate_python(data, self_instance=__pydantic_self__)
pydantic_core._pydantic_core.ValidationError: 1 validation error for Requirement
credits_required
  Input should be a valid integer [type=int_type, input_value=None, input_type=NoneType]
    For further information visit https://errors.pydantic.dev/2.5/v/int_type
INFO:     127.0.0.1:49670 - "GET /courses HTTP/1.1" 200 OK
INFO:     127.0.0.1:49673 - "GET /requirements HTTP/1.1" 500 Internal Server Error
ERROR:    Exception in ASGI application
Traceback (most recent call last):
  File "/Users/jazmin/Library/Python/3.9/lib/python/site-packages/uvicorn/protocols/http/httptools_impl.py", line 426, in run_asgi
    result = await app(  # type: ignore[func-returns-value]
  File "/Users/jazmin/Library/Python/3.9/lib/python/site-packages/uvicorn/middleware/proxy_headers.py", line 84, in __call__
    return await self.app(scope, receive, send)
  File "/Users/jazmin/Library/Python/3.9/lib/python/site-packages/fastapi/applications.py", line 1106, in __call__
    await super().__call__(scope, receive, send)
  File "/Users/jazmin/Library/Python/3.9/lib/python/site-packages/starlette/applications.py", line 122, in __call__
    await self.middleware_stack(scope, receive, send)
  File "/Users/jazmin/Library/Python/3.9/lib/python/site-packages/starlette/middleware/errors.py", line 184, in __call__
    raise exc
  File "/Users/jazmin/Library/Python/3.9/lib/python/site-packages/starlette/middleware/errors.py", line 162, in __call__
    await self.app(scope, receive, _send)
  File "/Users/jazmin/Library/Python/3.9/lib/python/site-packages/starlette/middleware/cors.py", line 91, in __call__
    await self.simple_response(scope, receive, send, request_headers=headers)
  File "/Users/jazmin/Library/Python/3.9/lib/python/site-packages/starlette/middleware/cors.py", line 146, in simple_response
    await self.app(scope, receive, send)
  File "/Users/jazmin/Library/Python/3.9/lib/python/site-packages/starlette/middleware/exceptions.py", line 79, in __call__
    raise exc
  File "/Users/jazmin/Library/Python/3.9/lib/python/site-packages/starlette/middleware/exceptions.py", line 68, in __call__
    await self.app(scope, receive, sender)
  File "/Users/jazmin/Library/Python/3.9/lib/python/site-packages/fastapi/middleware/asyncexitstack.py", line 20, in __call__
    raise e
  File "/Users/jazmin/Library/Python/3.9/lib/python/site-packages/fastapi/middleware/asyncexitstack.py", line 17, in __call__
    await self.app(scope, receive, send)
  File "/Users/jazmin/Library/Python/3.9/lib/python/site-packages/starlette/routing.py", line 718, in __call__
    await route.handle(scope, receive, send)
  File "/Users/jazmin/Library/Python/3.9/lib/python/site-packages/starlette/routing.py", line 276, in handle
    await self.app(scope, receive, send)
  File "/Users/jazmin/Library/Python/3.9/lib/python/site-packages/starlette/routing.py", line 66, in app
    response = await func(request)
  File "/Users/jazmin/Library/Python/3.9/lib/python/site-packages/fastapi/routing.py", line 274, in app
    raw_response = await run_endpoint_function(
  File "/Users/jazmin/Library/Python/3.9/lib/python/site-packages/fastapi/routing.py", line 191, in run_endpoint_function
    return await dependant.call(**values)
  File "/Users/jazmin/_dev/degree_planner/cursor/backend/main.py", line 177, in get_requirements
    return [Requirement(**req) for req in requirements_data]
  File "/Users/jazmin/_dev/degree_planner/cursor/backend/main.py", line 177, in <listcomp>
    return [Requirement(**req) for req in requirements_data]
  File "/Users/jazmin/Library/Python/3.9/lib/python/site-packages/pydantic/main.py", line 164, in __init__
    __pydantic_self__.__pydantic_validator__.validate_python(data, self_instance=__pydantic_self__)
pydantic_core._pydantic_core.ValidationError: 1 validation error for Requirement
credits_required
  Input should be a valid integer [type=int_type, input_value=None, input_type=NoneType]
    For further information visit https://errors.pydantic.dev/2.5/v/int_type
INFO:     None:0 - "GET /manifest.json HTTP/1.1" 404 Not Found
INFO:     127.0.0.1:49797 - "GET /courses HTTP/1.1" 200 OK
INFO:     127.0.0.1:49798 - "GET /requirements HTTP/1.1" 500 Internal Server Error
ERROR:    Exception in ASGI application
Traceback (most recent call last):
  File "/Users/jazmin/Library/Python/3.9/lib/python/site-packages/uvicorn/protocols/http/httptools_impl.py", line 426, in run_asgi
    result = await app(  # type: ignore[func-returns-value]
  File "/Users/jazmin/Library/Python/3.9/lib/python/site-packages/uvicorn/middleware/proxy_headers.py", line 84, in __call__
    return await self.app(scope, receive, send)
  File "/Users/jazmin/Library/Python/3.9/lib/python/site-packages/fastapi/applications.py", line 1106, in __call__
    await super().__call__(scope, receive, send)
  File "/Users/jazmin/Library/Python/3.9/lib/python/site-packages/starlette/applications.py", line 122, in __call__
    await self.middleware_stack(scope, receive, send)
  File "/Users/jazmin/Library/Python/3.9/lib/python/site-packages/starlette/middleware/errors.py", line 184, in __call__
    raise exc
  File "/Users/jazmin/Library/Python/3.9/lib/python/site-packages/starlette/middleware/errors.py", line 162, in __call__
    await self.app(scope, receive, _send)
  File "/Users/jazmin/Library/Python/3.9/lib/python/site-packages/starlette/middleware/cors.py", line 91, in __call__
    await self.simple_response(scope, receive, send, request_headers=headers)
  File "/Users/jazmin/Library/Python/3.9/lib/python/site-packages/starlette/middleware/cors.py", line 146, in simple_response
    await self.app(scope, receive, send)
  File "/Users/jazmin/Library/Python/3.9/lib/python/site-packages/starlette/middleware/exceptions.py", line 79, in __call__
    raise exc
  File "/Users/jazmin/Library/Python/3.9/lib/python/site-packages/starlette/middleware/exceptions.py", line 68, in __call__
    await self.app(scope, receive, sender)
  File "/Users/jazmin/Library/Python/3.9/lib/python/site-packages/fastapi/middleware/asyncexitstack.py", line 20, in __call__
    raise e
  File "/Users/jazmin/Library/Python/3.9/lib/python/site-packages/fastapi/middleware/asyncexitstack.py", line 17, in __call__
    await self.app(scope, receive, send)
  File "/Users/jazmin/Library/Python/3.9/lib/python/site-packages/starlette/routing.py", line 718, in __call__
    await route.handle(scope, receive, send)
  File "/Users/jazmin/Library/Python/3.9/lib/python/site-packages/starlette/routing.py", line 276, in handle
    await self.app(scope, receive, send)
  File "/Users/jazmin/Library/Python/3.9/lib/python/site-packages/starlette/routing.py", line 66, in app
    response = await func(request)
  File "/Users/jazmin/Library/Python/3.9/lib/python/site-packages/fastapi/routing.py", line 274, in app
    raw_response = await run_endpoint_function(
  File "/Users/jazmin/Library/Python/3.9/lib/python/site-packages/fastapi/routing.py", line 191, in run_endpoint_function
    return await dependant.call(**values)
  File "/Users/jazmin/_dev/degree_planner/cursor/backend/main.py", line 177, in get_requirements
    return [Requirement(**req) for req in requirements_data]
  File "/Users/jazmin/_dev/degree_planner/cursor/backend/main.py", line 177, in <listcomp>
    return [Requirement(**req) for req in requirements_data]
  File "/Users/jazmin/Library/Python/3.9/lib/python/site-packages/pydantic/main.py", line 164, in __init__
    __pydantic_self__.__pydantic_validator__.validate_python(data, self_instance=__pydantic_self__)
pydantic_core._pydantic_core.ValidationError: 1 validation error for Requirement
credits_required
  Input should be a valid integer [type=int_type, input_value=None, input_type=NoneType]
    For further information visit https://errors.pydantic.dev/2.5/v/int_type
INFO:     127.0.0.1:49800 - "GET /courses HTTP/1.1" 200 OK
INFO:     127.0.0.1:49802 - "GET /requirements HTTP/1.1" 500 Internal Server Error
ERROR:    Exception in ASGI application
Traceback (most recent call last):
  File "/Users/jazmin/Library/Python/3.9/lib/python/site-packages/uvicorn/protocols/http/httptools_impl.py", line 426, in run_asgi
    result = await app(  # type: ignore[func-returns-value]
  File "/Users/jazmin/Library/Python/3.9/lib/python/site-packages/uvicorn/middleware/proxy_headers.py", line 84, in __call__
    return await self.app(scope, receive, send)
  File "/Users/jazmin/Library/Python/3.9/lib/python/site-packages/fastapi/applications.py", line 1106, in __call__
    await super().__call__(scope, receive, send)
  File "/Users/jazmin/Library/Python/3.9/lib/python/site-packages/starlette/applications.py", line 122, in __call__
    await self.middleware_stack(scope, receive, send)
  File "/Users/jazmin/Library/Python/3.9/lib/python/site-packages/starlette/middleware/errors.py", line 184, in __call__
    raise exc
  File "/Users/jazmin/Library/Python/3.9/lib/python/site-packages/starlette/middleware/errors.py", line 162, in __call__
    await self.app(scope, receive, _send)
  File "/Users/jazmin/Library/Python/3.9/lib/python/site-packages/starlette/middleware/cors.py", line 91, in __call__
    await self.simple_response(scope, receive, send, request_headers=headers)
  File "/Users/jazmin/Library/Python/3.9/lib/python/site-packages/starlette/middleware/cors.py", line 146, in simple_response
    await self.app(scope, receive, send)
  File "/Users/jazmin/Library/Python/3.9/lib/python/site-packages/starlette/middleware/exceptions.py", line 79, in __call__
    raise exc
  File "/Users/jazmin/Library/Python/3.9/lib/python/site-packages/starlette/middleware/exceptions.py", line 68, in __call__
    await self.app(scope, receive, sender)
  File "/Users/jazmin/Library/Python/3.9/lib/python/site-packages/fastapi/middleware/asyncexitstack.py", line 20, in __call__
    raise e
  File "/Users/jazmin/Library/Python/3.9/lib/python/site-packages/fastapi/middleware/asyncexitstack.py", line 17, in __call__
    await self.app(scope, receive, send)
  File "/Users/jazmin/Library/Python/3.9/lib/python/site-packages/starlette/routing.py", line 718, in __call__
    await route.handle(scope, receive, send)
  File "/Users/jazmin/Library/Python/3.9/lib/python/site-packages/starlette/routing.py", line 276, in handle
    await self.app(scope, receive, send)
  File "/Users/jazmin/Library/Python/3.9/lib/python/site-packages/starlette/routing.py", line 66, in app
    response = await func(request)
  File "/Users/jazmin/Library/Python/3.9/lib/python/site-packages/fastapi/routing.py", line 274, in app
    raw_response = await run_endpoint_function(
  File "/Users/jazmin/Library/Python/3.9/lib/python/site-packages/fastapi/routing.py", line 191, in run_endpoint_function
    return await dependant.call(**values)
  File "/Users/jazmin/_dev/degree_planner/cursor/backend/main.py", line 177, in get_requirements
    return [Requirement(**req) for req in requirements_data]
  File "/Users/jazmin/_dev/degree_planner/cursor/backend/main.py", line 177, in <listcomp>
    return [Requirement(**req) for req in requirements_data]
  File "/Users/jazmin/Library/Python/3.9/lib/python/site-packages/pydantic/main.py", line 164, in __init__
    __pydantic_self__.__pydantic_validator__.validate_python(data, self_instance=__pydantic_self__)
pydantic_core._pydantic_core.ValidationError: 1 validation error for Requirement
credits_required
  Input should be a valid integer [type=int_type, input_value=None, input_type=NoneType]
    For further information visit https://errors.pydantic.dev/2.5/v/int_type
INFO:     None:0 - "GET /manifest.json HTTP/1.1" 404 Not Found
INFO:     None:0 - "GET /favicon.ico HTTP/1.1" 404 Not Found
INFO:     127.0.0.1:49874 - "GET /courses HTTP/1.1" 200 OK
INFO:     127.0.0.1:49875 - "GET /requirements HTTP/1.1" 500 Internal Server Error
ERROR:    Exception in ASGI application
Traceback (most recent call last):
  File "/Users/jazmin/Library/Python/3.9/lib/python/site-packages/uvicorn/protocols/http/httptools_impl.py", line 426, in run_asgi
    result = await app(  # type: ignore[func-returns-value]
  File "/Users/jazmin/Library/Python/3.9/lib/python/site-packages/uvicorn/middleware/proxy_headers.py", line 84, in __call__
    return await self.app(scope, receive, send)
  File "/Users/jazmin/Library/Python/3.9/lib/python/site-packages/fastapi/applications.py", line 1106, in __call__
    await super().__call__(scope, receive, send)
  File "/Users/jazmin/Library/Python/3.9/lib/python/site-packages/starlette/applications.py", line 122, in __call__
    await self.middleware_stack(scope, receive, send)
  File "/Users/jazmin/Library/Python/3.9/lib/python/site-packages/starlette/middleware/errors.py", line 184, in __call__
    raise exc
  File "/Users/jazmin/Library/Python/3.9/lib/python/site-packages/starlette/middleware/errors.py", line 162, in __call__
    await self.app(scope, receive, _send)
  File "/Users/jazmin/Library/Python/3.9/lib/python/site-packages/starlette/middleware/cors.py", line 91, in __call__
    await self.simple_response(scope, receive, send, request_headers=headers)
  File "/Users/jazmin/Library/Python/3.9/lib/python/site-packages/starlette/middleware/cors.py", line 146, in simple_response
    await self.app(scope, receive, send)
  File "/Users/jazmin/Library/Python/3.9/lib/python/site-packages/starlette/middleware/exceptions.py", line 79, in __call__
    raise exc
  File "/Users/jazmin/Library/Python/3.9/lib/python/site-packages/starlette/middleware/exceptions.py", line 68, in __call__
    await self.app(scope, receive, sender)
  File "/Users/jazmin/Library/Python/3.9/lib/python/site-packages/fastapi/middleware/asyncexitstack.py", line 20, in __call__
    raise e
  File "/Users/jazmin/Library/Python/3.9/lib/python/site-packages/fastapi/middleware/asyncexitstack.py", line 17, in __call__
    await self.app(scope, receive, send)
  File "/Users/jazmin/Library/Python/3.9/lib/python/site-packages/starlette/routing.py", line 718, in __call__
    await route.handle(scope, receive, send)
  File "/Users/jazmin/Library/Python/3.9/lib/python/site-packages/starlette/routing.py", line 276, in handle
    await self.app(scope, receive, send)
  File "/Users/jazmin/Library/Python/3.9/lib/python/site-packages/starlette/routing.py", line 66, in app
    response = await func(request)
  File "/Users/jazmin/Library/Python/3.9/lib/python/site-packages/fastapi/routing.py", line 274, in app
    raw_response = await run_endpoint_function(
  File "/Users/jazmin/Library/Python/3.9/lib/python/site-packages/fastapi/routing.py", line 191, in run_endpoint_function
    return await dependant.call(**values)
  File "/Users/jazmin/_dev/degree_planner/cursor/backend/main.py", line 177, in get_requirements
    return [Requirement(**req) for req in requirements_data]
  File "/Users/jazmin/_dev/degree_planner/cursor/backend/main.py", line 177, in <listcomp>
    return [Requirement(**req) for req in requirements_data]
  File "/Users/jazmin/Library/Python/3.9/lib/python/site-packages/pydantic/main.py", line 164, in __init__
    __pydantic_self__.__pydantic_validator__.validate_python(data, self_instance=__pydantic_self__)
pydantic_core._pydantic_core.ValidationError: 1 validation error for Requirement
credits_required
  Input should be a valid integer [type=int_type, input_value=None, input_type=NoneType]
    For further information visit https://errors.pydantic.dev/2.5/v/int_type
INFO:     127.0.0.1:49877 - "GET /courses HTTP/1.1" 200 OK
INFO:     127.0.0.1:49879 - "GET /requirements HTTP/1.1" 500 Internal Server Error
ERROR:    Exception in ASGI application
Traceback (most recent call last):
  File "/Users/jazmin/Library/Python/3.9/lib/python/site-packages/uvicorn/protocols/http/httptools_impl.py", line 426, in run_asgi
    result = await app(  # type: ignore[func-returns-value]
  File "/Users/jazmin/Library/Python/3.9/lib/python/site-packages/uvicorn/middleware/proxy_headers.py", line 84, in __call__
    return await self.app(scope, receive, send)
  File "/Users/jazmin/Library/Python/3.9/lib/python/site-packages/fastapi/applications.py", line 1106, in __call__
    await super().__call__(scope, receive, send)
  File "/Users/jazmin/Library/Python/3.9/lib/python/site-packages/starlette/applications.py", line 122, in __call__
    await self.middleware_stack(scope, receive, send)
  File "/Users/jazmin/Library/Python/3.9/lib/python/site-packages/starlette/middleware/errors.py", line 184, in __call__
    raise exc
  File "/Users/jazmin/Library/Python/3.9/lib/python/site-packages/starlette/middleware/errors.py", line 162, in __call__
    await self.app(scope, receive, _send)
  File "/Users/jazmin/Library/Python/3.9/lib/python/site-packages/starlette/middleware/cors.py", line 91, in __call__
    await self.simple_response(scope, receive, send, request_headers=headers)
  File "/Users/jazmin/Library/Python/3.9/lib/python/site-packages/starlette/middleware/cors.py", line 146, in simple_response
    await self.app(scope, receive, send)
  File "/Users/jazmin/Library/Python/3.9/lib/python/site-packages/starlette/middleware/exceptions.py", line 79, in __call__
    raise exc
  File "/Users/jazmin/Library/Python/3.9/lib/python/site-packages/starlette/middleware/exceptions.py", line 68, in __call__
    await self.app(scope, receive, sender)
  File "/Users/jazmin/Library/Python/3.9/lib/python/site-packages/fastapi/middleware/asyncexitstack.py", line 20, in __call__
    raise e
  File "/Users/jazmin/Library/Python/3.9/lib/python/site-packages/fastapi/middleware/asyncexitstack.py", line 17, in __call__
    await self.app(scope, receive, send)
  File "/Users/jazmin/Library/Python/3.9/lib/python/site-packages/starlette/routing.py", line 718, in __call__
    await route.handle(scope, receive, send)
  File "/Users/jazmin/Library/Python/3.9/lib/python/site-packages/starlette/routing.py", line 276, in handle
    await self.app(scope, receive, send)
  File "/Users/jazmin/Library/Python/3.9/lib/python/site-packages/starlette/routing.py", line 66, in app
    response = await func(request)
  File "/Users/jazmin/Library/Python/3.9/lib/python/site-packages/fastapi/routing.py", line 274, in app
    raw_response = await run_endpoint_function(
  File "/Users/jazmin/Library/Python/3.9/lib/python/site-packages/fastapi/routing.py", line 191, in run_endpoint_function
    return await dependant.call(**values)
  File "/Users/jazmin/_dev/degree_planner/cursor/backend/main.py", line 177, in get_requirements
    return [Requirement(**req) for req in requirements_data]
  File "/Users/jazmin/_dev/degree_planner/cursor/backend/main.py", line 177, in <listcomp>
    return [Requirement(**req) for req in requirements_data]
  File "/Users/jazmin/Library/Python/3.9/lib/python/site-packages/pydantic/main.py", line 164, in __init__
    __pydantic_self__.__pydantic_validator__.validate_python(data, self_instance=__pydantic_self__)
pydantic_core._pydantic_core.ValidationError: 1 validation error for Requirement
credits_required
  Input should be a valid integer [type=int_type, input_value=None, input_type=NoneType]
    For further information visit https://errors.pydantic.dev/2.5/v/int_type
INFO:     None:0 - "GET /manifest.json HTTP/1.1" 404 Not Found
INFO:     127.0.0.1:49915 - "GET /courses HTTP/1.1" 200 OK
INFO:     127.0.0.1:49916 - "GET /requirements HTTP/1.1" 500 Internal Server Error
ERROR:    Exception in ASGI application
Traceback (most recent call last):
  File "/Users/jazmin/Library/Python/3.9/lib/python/site-packages/uvicorn/protocols/http/httptools_impl.py", line 426, in run_asgi
    result = await app(  # type: ignore[func-returns-value]
  File "/Users/jazmin/Library/Python/3.9/lib/python/site-packages/uvicorn/middleware/proxy_headers.py", line 84, in __call__
    return await self.app(scope, receive, send)
  File "/Users/jazmin/Library/Python/3.9/lib/python/site-packages/fastapi/applications.py", line 1106, in __call__
    await super().__call__(scope, receive, send)
  File "/Users/jazmin/Library/Python/3.9/lib/python/site-packages/starlette/applications.py", line 122, in __call__
    await self.middleware_stack(scope, receive, send)
  File "/Users/jazmin/Library/Python/3.9/lib/python/site-packages/starlette/middleware/errors.py", line 184, in __call__
    raise exc
  File "/Users/jazmin/Library/Python/3.9/lib/python/site-packages/starlette/middleware/errors.py", line 162, in __call__
    await self.app(scope, receive, _send)
  File "/Users/jazmin/Library/Python/3.9/lib/python/site-packages/starlette/middleware/cors.py", line 91, in __call__
    await self.simple_response(scope, receive, send, request_headers=headers)
  File "/Users/jazmin/Library/Python/3.9/lib/python/site-packages/starlette/middleware/cors.py", line 146, in simple_response
    await self.app(scope, receive, send)
  File "/Users/jazmin/Library/Python/3.9/lib/python/site-packages/starlette/middleware/exceptions.py", line 79, in __call__
    raise exc
  File "/Users/jazmin/Library/Python/3.9/lib/python/site-packages/starlette/middleware/exceptions.py", line 68, in __call__
    await self.app(scope, receive, sender)
  File "/Users/jazmin/Library/Python/3.9/lib/python/site-packages/fastapi/middleware/asyncexitstack.py", line 20, in __call__
    raise e
  File "/Users/jazmin/Library/Python/3.9/lib/python/site-packages/fastapi/middleware/asyncexitstack.py", line 17, in __call__
    await self.app(scope, receive, send)
  File "/Users/jazmin/Library/Python/3.9/lib/python/site-packages/starlette/routing.py", line 718, in __call__
    await route.handle(scope, receive, send)
  File "/Users/jazmin/Library/Python/3.9/lib/python/site-packages/starlette/routing.py", line 276, in handle
    await self.app(scope, receive, send)
  File "/Users/jazmin/Library/Python/3.9/lib/python/site-packages/starlette/routing.py", line 66, in app
    response = await func(request)
  File "/Users/jazmin/Library/Python/3.9/lib/python/site-packages/fastapi/routing.py", line 274, in app
    raw_response = await run_endpoint_function(
  File "/Users/jazmin/Library/Python/3.9/lib/python/site-packages/fastapi/routing.py", line 191, in run_endpoint_function
    return await dependant.call(**values)
  File "/Users/jazmin/_dev/degree_planner/cursor/backend/main.py", line 177, in get_requirements
    return [Requirement(**req) for req in requirements_data]
  File "/Users/jazmin/_dev/degree_planner/cursor/backend/main.py", line 177, in <listcomp>
    return [Requirement(**req) for req in requirements_data]
  File "/Users/jazmin/Library/Python/3.9/lib/python/site-packages/pydantic/main.py", line 164, in __init__
    __pydantic_self__.__pydantic_validator__.validate_python(data, self_instance=__pydantic_self__)
pydantic_core._pydantic_core.ValidationError: 1 validation error for Requirement
credits_required
  Input should be a valid integer [type=int_type, input_value=None, input_type=NoneType]
    For further information visit https://errors.pydantic.dev/2.5/v/int_type
INFO:     127.0.0.1:49918 - "GET /courses HTTP/1.1" 200 OK
INFO:     127.0.0.1:49920 - "GET /requirements HTTP/1.1" 500 Internal Server Error
ERROR:    Exception in ASGI application
Traceback (most recent call last):
  File "/Users/jazmin/Library/Python/3.9/lib/python/site-packages/uvicorn/protocols/http/httptools_impl.py", line 426, in run_asgi
    result = await app(  # type: ignore[func-returns-value]
  File "/Users/jazmin/Library/Python/3.9/lib/python/site-packages/uvicorn/middleware/proxy_headers.py", line 84, in __call__
    return await self.app(scope, receive, send)
  File "/Users/jazmin/Library/Python/3.9/lib/python/site-packages/fastapi/applications.py", line 1106, in __call__
    await super().__call__(scope, receive, send)
  File "/Users/jazmin/Library/Python/3.9/lib/python/site-packages/starlette/applications.py", line 122, in __call__
    await self.middleware_stack(scope, receive, send)
  File "/Users/jazmin/Library/Python/3.9/lib/python/site-packages/starlette/middleware/errors.py", line 184, in __call__
    raise exc
  File "/Users/jazmin/Library/Python/3.9/lib/python/site-packages/starlette/middleware/errors.py", line 162, in __call__
    await self.app(scope, receive, _send)
  File "/Users/jazmin/Library/Python/3.9/lib/python/site-packages/starlette/middleware/cors.py", line 91, in __call__
    await self.simple_response(scope, receive, send, request_headers=headers)
  File "/Users/jazmin/Library/Python/3.9/lib/python/site-packages/starlette/middleware/cors.py", line 146, in simple_response
    await self.app(scope, receive, send)
  File "/Users/jazmin/Library/Python/3.9/lib/python/site-packages/starlette/middleware/exceptions.py", line 79, in __call__
    raise exc
  File "/Users/jazmin/Library/Python/3.9/lib/python/site-packages/starlette/middleware/exceptions.py", line 68, in __call__
    await self.app(scope, receive, sender)
  File "/Users/jazmin/Library/Python/3.9/lib/python/site-packages/fastapi/middleware/asyncexitstack.py", line 20, in __call__
    raise e
  File "/Users/jazmin/Library/Python/3.9/lib/python/site-packages/fastapi/middleware/asyncexitstack.py", line 17, in __call__
    await self.app(scope, receive, send)
  File "/Users/jazmin/Library/Python/3.9/lib/python/site-packages/starlette/routing.py", line 718, in __call__
    await route.handle(scope, receive, send)
  File "/Users/jazmin/Library/Python/3.9/lib/python/site-packages/starlette/routing.py", line 276, in handle
    await self.app(scope, receive, send)
  File "/Users/jazmin/Library/Python/3.9/lib/python/site-packages/starlette/routing.py", line 66, in app
    response = await func(request)
  File "/Users/jazmin/Library/Python/3.9/lib/python/site-packages/fastapi/routing.py", line 274, in app
    raw_response = await run_endpoint_function(
  File "/Users/jazmin/Library/Python/3.9/lib/python/site-packages/fastapi/routing.py", line 191, in run_endpoint_function
    return await dependant.call(**values)
  File "/Users/jazmin/_dev/degree_planner/cursor/backend/main.py", line 177, in get_requirements
    return [Requirement(**req) for req in requirements_data]
  File "/Users/jazmin/_dev/degree_planner/cursor/backend/main.py", line 177, in <listcomp>
    return [Requirement(**req) for req in requirements_data]
  File "/Users/jazmin/Library/Python/3.9/lib/python/site-packages/pydantic/main.py", line 164, in __init__
    __pydantic_self__.__pydantic_validator__.validate_python(data, self_instance=__pydantic_self__)
pydantic_core._pydantic_core.ValidationError: 1 validation error for Requirement
credits_required
  Input should be a valid integer [type=int_type, input_value=None, input_type=NoneType]
    For further information visit https://errors.pydantic.dev/2.5/v/int_type
INFO:     None:0 - "GET /manifest.json HTTP/1.1" 404 Not Found
INFO:     127.0.0.1:50033 - "GET /courses HTTP/1.1" 200 OK
INFO:     127.0.0.1:50034 - "GET /requirements HTTP/1.1" 500 Internal Server Error
ERROR:    Exception in ASGI application
Traceback (most recent call last):
  File "/Users/jazmin/Library/Python/3.9/lib/python/site-packages/uvicorn/protocols/http/httptools_impl.py", line 426, in run_asgi
    result = await app(  # type: ignore[func-returns-value]
  File "/Users/jazmin/Library/Python/3.9/lib/python/site-packages/uvicorn/middleware/proxy_headers.py", line 84, in __call__
    return await self.app(scope, receive, send)
  File "/Users/jazmin/Library/Python/3.9/lib/python/site-packages/fastapi/applications.py", line 1106, in __call__
    await super().__call__(scope, receive, send)
  File "/Users/jazmin/Library/Python/3.9/lib/python/site-packages/starlette/applications.py", line 122, in __call__
    await self.middleware_stack(scope, receive, send)
  File "/Users/jazmin/Library/Python/3.9/lib/python/site-packages/starlette/middleware/errors.py", line 184, in __call__
    raise exc
  File "/Users/jazmin/Library/Python/3.9/lib/python/site-packages/starlette/middleware/errors.py", line 162, in __call__
    await self.app(scope, receive, _send)
  File "/Users/jazmin/Library/Python/3.9/lib/python/site-packages/starlette/middleware/cors.py", line 91, in __call__
    await self.simple_response(scope, receive, send, request_headers=headers)
  File "/Users/jazmin/Library/Python/3.9/lib/python/site-packages/starlette/middleware/cors.py", line 146, in simple_response
    await self.app(scope, receive, send)
  File "/Users/jazmin/Library/Python/3.9/lib/python/site-packages/starlette/middleware/exceptions.py", line 79, in __call__
    raise exc
  File "/Users/jazmin/Library/Python/3.9/lib/python/site-packages/starlette/middleware/exceptions.py", line 68, in __call__
    await self.app(scope, receive, sender)
  File "/Users/jazmin/Library/Python/3.9/lib/python/site-packages/fastapi/middleware/asyncexitstack.py", line 20, in __call__
    raise e
  File "/Users/jazmin/Library/Python/3.9/lib/python/site-packages/fastapi/middleware/asyncexitstack.py", line 17, in __call__
    await self.app(scope, receive, send)
  File "/Users/jazmin/Library/Python/3.9/lib/python/site-packages/starlette/routing.py", line 718, in __call__
    await route.handle(scope, receive, send)
  File "/Users/jazmin/Library/Python/3.9/lib/python/site-packages/starlette/routing.py", line 276, in handle
    await self.app(scope, receive, send)
  File "/Users/jazmin/Library/Python/3.9/lib/python/site-packages/starlette/routing.py", line 66, in app
    response = await func(request)
  File "/Users/jazmin/Library/Python/3.9/lib/python/site-packages/fastapi/routing.py", line 274, in app
    raw_response = await run_endpoint_function(
  File "/Users/jazmin/Library/Python/3.9/lib/python/site-packages/fastapi/routing.py", line 191, in run_endpoint_function
    return await dependant.call(**values)
  File "/Users/jazmin/_dev/degree_planner/cursor/backend/main.py", line 177, in get_requirements
    return [Requirement(**req) for req in requirements_data]
  File "/Users/jazmin/_dev/degree_planner/cursor/backend/main.py", line 177, in <listcomp>
    return [Requirement(**req) for req in requirements_data]
  File "/Users/jazmin/Library/Python/3.9/lib/python/site-packages/pydantic/main.py", line 164, in __init__
    __pydantic_self__.__pydantic_validator__.validate_python(data, self_instance=__pydantic_self__)
pydantic_core._pydantic_core.ValidationError: 1 validation error for Requirement
credits_required
  Input should be a valid integer [type=int_type, input_value=None, input_type=NoneType]
    For further information visit https://errors.pydantic.dev/2.5/v/int_type
INFO:     127.0.0.1:50036 - "GET /courses HTTP/1.1" 200 OK
INFO:     127.0.0.1:50038 - "GET /requirements HTTP/1.1" 500 Internal Server Error
ERROR:    Exception in ASGI application
Traceback (most recent call last):
  File "/Users/jazmin/Library/Python/3.9/lib/python/site-packages/uvicorn/protocols/http/httptools_impl.py", line 426, in run_asgi
    result = await app(  # type: ignore[func-returns-value]
  File "/Users/jazmin/Library/Python/3.9/lib/python/site-packages/uvicorn/middleware/proxy_headers.py", line 84, in __call__
    return await self.app(scope, receive, send)
  File "/Users/jazmin/Library/Python/3.9/lib/python/site-packages/fastapi/applications.py", line 1106, in __call__
    await super().__call__(scope, receive, send)
  File "/Users/jazmin/Library/Python/3.9/lib/python/site-packages/starlette/applications.py", line 122, in __call__
    await self.middleware_stack(scope, receive, send)
  File "/Users/jazmin/Library/Python/3.9/lib/python/site-packages/starlette/middleware/errors.py", line 184, in __call__
    raise exc
  File "/Users/jazmin/Library/Python/3.9/lib/python/site-packages/starlette/middleware/errors.py", line 162, in __call__
    await self.app(scope, receive, _send)
  File "/Users/jazmin/Library/Python/3.9/lib/python/site-packages/starlette/middleware/cors.py", line 91, in __call__
    await self.simple_response(scope, receive, send, request_headers=headers)
  File "/Users/jazmin/Library/Python/3.9/lib/python/site-packages/starlette/middleware/cors.py", line 146, in simple_response
    await self.app(scope, receive, send)
  File "/Users/jazmin/Library/Python/3.9/lib/python/site-packages/starlette/middleware/exceptions.py", line 79, in __call__
    raise exc
  File "/Users/jazmin/Library/Python/3.9/lib/python/site-packages/starlette/middleware/exceptions.py", line 68, in __call__
    await self.app(scope, receive, sender)
  File "/Users/jazmin/Library/Python/3.9/lib/python/site-packages/fastapi/middleware/asyncexitstack.py", line 20, in __call__
    raise e
  File "/Users/jazmin/Library/Python/3.9/lib/python/site-packages/fastapi/middleware/asyncexitstack.py", line 17, in __call__
    await self.app(scope, receive, send)
  File "/Users/jazmin/Library/Python/3.9/lib/python/site-packages/starlette/routing.py", line 718, in __call__
    await route.handle(scope, receive, send)
  File "/Users/jazmin/Library/Python/3.9/lib/python/site-packages/starlette/routing.py", line 276, in handle
    await self.app(scope, receive, send)
  File "/Users/jazmin/Library/Python/3.9/lib/python/site-packages/starlette/routing.py", line 66, in app
    response = await func(request)
  File "/Users/jazmin/Library/Python/3.9/lib/python/site-packages/fastapi/routing.py", line 274, in app
    raw_response = await run_endpoint_function(
  File "/Users/jazmin/Library/Python/3.9/lib/python/site-packages/fastapi/routing.py", line 191, in run_endpoint_function
    return await dependant.call(**values)
  File "/Users/jazmin/_dev/degree_planner/cursor/backend/main.py", line 177, in get_requirements
    return [Requirement(**req) for req in requirements_data]
  File "/Users/jazmin/_dev/degree_planner/cursor/backend/main.py", line 177, in <listcomp>
    return [Requirement(**req) for req in requirements_data]
  File "/Users/jazmin/Library/Python/3.9/lib/python/site-packages/pydantic/main.py", line 164, in __init__
    __pydantic_self__.__pydantic_validator__.validate_python(data, self_instance=__pydantic_self__)
pydantic_core._pydantic_core.ValidationError: 1 validation error for Requirement
credits_required
  Input should be a valid integer [type=int_type, input_value=None, input_type=NoneType]
    For further information visit https://errors.pydantic.dev/2.5/v/int_type
INFO:     None:0 - "GET /manifest.json HTTP/1.1" 404 Not Found
